{"name": "test_authorization_with_invalid_credentials_negative", "status": "broken", "statusDetails": {"message": "selenium.common.exceptions.TimeoutException: Message: \nStacktrace:\n#0 0x561c93e3ef33 <unknown>\n#1 0x561c93b89118 <unknown>\n#2 0x561c93bbf3f7 <unknown>\n#3 0x561c93bbf5c1 <unknown>\n#4 0x561c93bf25c4 <unknown>\n#5 0x561c93bdcf9d <unknown>\n#6 0x561c93bf02e4 <unknown>\n#7 0x561c93bdce63 <unknown>\n#8 0x561c93bb282a <unknown>\n#9 0x561c93bb3985 <unknown>\n#10 0x561c93e834cd <unknown>\n#11 0x561c93e875ec <unknown>\n#12 0x561c93e6d71e <unknown>\n#13 0x561c93e88238 <unknown>\n#14 0x561c93e62870 <unknown>\n#15 0x561c93ea4608 <unknown>\n#16 0x561c93ea4788 <unknown>\n#17 0x561c93ebef1d <unknown>\n#18 0x7f3a5d727609 <unknown>", "trace": "self = <tests.negative_tests.test_authorization_user_negative.TestAuthorizationRegistrationNegative object at 0x7f1b2f4e8940>\n\n    @allure.description(\"In that test we try login with invalid credentials\")\n    @allure.severity(severity_level=\"CRITICAL\")\n    def test_authorization_with_invalid_credentials_negative(self):\n    \tautomation_practice = AutomationpracticeApp(self.driver)\n    \tsign_in = automation_practice.sign_in_page\n    \tautomation_practice.go_to(\"index.php?controller=authentication&back=my-account\")\n>   \tsign_in.authorization_in_account()\n\ntests/negative_tests/test_authorization_user_negative.py:14: \n_ _ _ _ _ _ _ _ _ _ _ _ _ _ _ _ _ _ _ _ _ _ _ _ _ _ _ _ _ _ _ _ _ _ _ _ _ _ _ _ _ _ _ _ _ _ _ _ _ _ _ _ _ _ _ _ _ _ _ _ _ _ _ _ _ _ _ _ _ _ _ _ _ _ _ _ _ _ _ _ _ _ _ _ _ _ _ _ _ _ _ _ _ _ _ _ _ _ _ _ _ \nframework/features/automationpractice/sing_in_page.py:22: in authorization_in_account\n    email_field = self.element.email_field_for_authorization.find_if_visible()\nframework/utils.py:19: in find_if_visible\n    return self.__wait.until(ec.visibility_of_element_located(self.locator))\n_ _ _ _ _ _ _ _ _ _ _ _ _ _ _ _ _ _ _ _ _ _ _ _ _ _ _ _ _ _ _ _ _ _ _ _ _ _ _ _ _ _ _ _ _ _ _ _ _ _ _ _ _ _ _ _ _ _ _ _ _ _ _ _ _ _ _ _ _ _ _ _ _ _ _ _ _ _ _ _ _ _ _ _ _ _ _ _ _ _ _ _ _ _ _ _ _ _ _ _ _ \n\nself = <selenium.webdriver.support.wait.WebDriverWait (session=\"35c48d2e52b16bcbf883532b2aa6f5ed\")>, method = <function visibility_of_element_located.<locals>._predicate at 0x7f1b2f5c99d0>, message = ''\n\n    def until(self, method, message: str = \"\"):\n        \"\"\"Calls the method provided with the driver as an argument until the \\\n        return value does not evaluate to ``False``.\n    \n        :param method: callable(WebDriver)\n        :param message: optional message for :exc:`TimeoutException`\n        :returns: the result of the last call to `method`\n        :raises: :exc:`selenium.common.exceptions.TimeoutException` if timeout occurs\n        \"\"\"\n        screen = None\n        stacktrace = None\n    \n        end_time = time.monotonic() + self._timeout\n        while True:\n            try:\n                value = method(self._driver)\n                if value:\n                    return value\n            except self._ignored_exceptions as exc:\n                screen = getattr(exc, 'screen', None)\n                stacktrace = getattr(exc, 'stacktrace', None)\n            time.sleep(self._poll)\n            if time.monotonic() > end_time:\n                break\n>       raise TimeoutException(message, screen, stacktrace)\nE       selenium.common.exceptions.TimeoutException: Message: \nE       Stacktrace:\nE       #0 0x561c93e3ef33 <unknown>\nE       #1 0x561c93b89118 <unknown>\nE       #2 0x561c93bbf3f7 <unknown>\nE       #3 0x561c93bbf5c1 <unknown>\nE       #4 0x561c93bf25c4 <unknown>\nE       #5 0x561c93bdcf9d <unknown>\nE       #6 0x561c93bf02e4 <unknown>\nE       #7 0x561c93bdce63 <unknown>\nE       #8 0x561c93bb282a <unknown>\nE       #9 0x561c93bb3985 <unknown>\nE       #10 0x561c93e834cd <unknown>\nE       #11 0x561c93e875ec <unknown>\nE       #12 0x561c93e6d71e <unknown>\nE       #13 0x561c93e88238 <unknown>\nE       #14 0x561c93e62870 <unknown>\nE       #15 0x561c93ea4608 <unknown>\nE       #16 0x561c93ea4788 <unknown>\nE       #17 0x561c93ebef1d <unknown>\nE       #18 0x7f3a5d727609 <unknown>\n\n.venv/lib/python3.9/site-packages/selenium/webdriver/support/wait.py:90: TimeoutException"}, "description": "In that test we try login with invalid credentials", "start": 1658167317690, "stop": 1658167349055, "uuid": "a29a40ac-f31d-43b9-9586-96869680a97a", "historyId": "c1c8d9ab315ced79f61d6f2b0f6dbe24", "testCaseId": "99b3d4031e3c9193204afd98901cc2c8", "fullName": "tests.negative_tests.test_authorization_user_negative.TestAuthorizationRegistrationNegative#test_authorization_with_invalid_credentials_negative", "labels": [{"name": "severity", "value": "CRITICAL"}, {"name": "tag", "value": "@pytest.mark.usefixtures('set_up_webdriver')"}, {"name": "parentSuite", "value": "tests.negative_tests"}, {"name": "suite", "value": "test_authorization_user_negative"}, {"name": "subSuite", "value": "TestAuthorizationRegistrationNegative"}, {"name": "host", "value": "vladislav-G3-3579"}, {"name": "thread", "value": "100642-MainThread"}, {"name": "framework", "value": "pytest"}, {"name": "language", "value": "cpython3"}, {"name": "package", "value": "tests.negative_tests.test_authorization_user_negative"}]}