{"name": "test_authorization_with_invalid_credentials_negative", "status": "broken", "statusDetails": {"message": "selenium.common.exceptions.TimeoutException: Message: \nStacktrace:\n#0 0x5652e6e62f33 <unknown>\n#1 0x5652e6bad118 <unknown>\n#2 0x5652e6be33f7 <unknown>\n#3 0x5652e6be35c1 <unknown>\n#4 0x5652e6c165c4 <unknown>\n#5 0x5652e6c00f9d <unknown>\n#6 0x5652e6c142e4 <unknown>\n#7 0x5652e6c00e63 <unknown>\n#8 0x5652e6bd682a <unknown>\n#9 0x5652e6bd7985 <unknown>\n#10 0x5652e6ea74cd <unknown>\n#11 0x5652e6eab5ec <unknown>\n#12 0x5652e6e9171e <unknown>\n#13 0x5652e6eac238 <unknown>\n#14 0x5652e6e86870 <unknown>\n#15 0x5652e6ec8608 <unknown>\n#16 0x5652e6ec8788 <unknown>\n#17 0x5652e6ee2f1d <unknown>\n#18 0x7fcb7f12a609 <unknown>", "trace": "self = <tests.negative_tests.test_authorization_user_negative.TestAuthorizationRegistrationNegative object at 0x7f1b2f3e43d0>\n\n    @allure.description(\"In that test we try login with invalid credentials\")\n    @allure.severity(severity_level=\"CRITICAL\")\n    def test_authorization_with_invalid_credentials_negative(self):\n    \tautomation_practice = AutomationpracticeApp(self.driver)\n    \tsign_in = automation_practice.sign_in_page\n    \tautomation_practice.go_to(\"index.php?controller=authentication&back=my-account\")\n>   \tsign_in.authorization_in_account()\n\ntests/negative_tests/test_authorization_user_negative.py:14: \n_ _ _ _ _ _ _ _ _ _ _ _ _ _ _ _ _ _ _ _ _ _ _ _ _ _ _ _ _ _ _ _ _ _ _ _ _ _ _ _ _ _ _ _ _ _ _ _ _ _ _ _ _ _ _ _ _ _ _ _ _ _ _ _ _ _ _ _ _ _ _ _ _ _ _ _ _ _ _ _ _ _ _ _ _ _ _ _ _ _ _ _ _ _ _ _ _ _ _ _ _ \nframework/features/automationpractice/sing_in_page.py:22: in authorization_in_account\n    email_field = self.element.email_field_for_authorization.find_if_visible()\nframework/utils.py:19: in find_if_visible\n    return self.__wait.until(ec.visibility_of_element_located(self.locator))\n_ _ _ _ _ _ _ _ _ _ _ _ _ _ _ _ _ _ _ _ _ _ _ _ _ _ _ _ _ _ _ _ _ _ _ _ _ _ _ _ _ _ _ _ _ _ _ _ _ _ _ _ _ _ _ _ _ _ _ _ _ _ _ _ _ _ _ _ _ _ _ _ _ _ _ _ _ _ _ _ _ _ _ _ _ _ _ _ _ _ _ _ _ _ _ _ _ _ _ _ _ \n\nself = <selenium.webdriver.support.wait.WebDriverWait (session=\"3f00e1f2c5c0eafa935768034e0cc2e2\")>, method = <function visibility_of_element_located.<locals>._predicate at 0x7f1b2f3def70>, message = ''\n\n    def until(self, method, message: str = \"\"):\n        \"\"\"Calls the method provided with the driver as an argument until the \\\n        return value does not evaluate to ``False``.\n    \n        :param method: callable(WebDriver)\n        :param message: optional message for :exc:`TimeoutException`\n        :returns: the result of the last call to `method`\n        :raises: :exc:`selenium.common.exceptions.TimeoutException` if timeout occurs\n        \"\"\"\n        screen = None\n        stacktrace = None\n    \n        end_time = time.monotonic() + self._timeout\n        while True:\n            try:\n                value = method(self._driver)\n                if value:\n                    return value\n            except self._ignored_exceptions as exc:\n                screen = getattr(exc, 'screen', None)\n                stacktrace = getattr(exc, 'stacktrace', None)\n            time.sleep(self._poll)\n            if time.monotonic() > end_time:\n                break\n>       raise TimeoutException(message, screen, stacktrace)\nE       selenium.common.exceptions.TimeoutException: Message: \nE       Stacktrace:\nE       #0 0x5652e6e62f33 <unknown>\nE       #1 0x5652e6bad118 <unknown>\nE       #2 0x5652e6be33f7 <unknown>\nE       #3 0x5652e6be35c1 <unknown>\nE       #4 0x5652e6c165c4 <unknown>\nE       #5 0x5652e6c00f9d <unknown>\nE       #6 0x5652e6c142e4 <unknown>\nE       #7 0x5652e6c00e63 <unknown>\nE       #8 0x5652e6bd682a <unknown>\nE       #9 0x5652e6bd7985 <unknown>\nE       #10 0x5652e6ea74cd <unknown>\nE       #11 0x5652e6eab5ec <unknown>\nE       #12 0x5652e6e9171e <unknown>\nE       #13 0x5652e6eac238 <unknown>\nE       #14 0x5652e6e86870 <unknown>\nE       #15 0x5652e6ec8608 <unknown>\nE       #16 0x5652e6ec8788 <unknown>\nE       #17 0x5652e6ee2f1d <unknown>\nE       #18 0x7fcb7f12a609 <unknown>\n\n.venv/lib/python3.9/site-packages/selenium/webdriver/support/wait.py:90: TimeoutException"}, "description": "In that test we try login with invalid credentials", "start": 1658167349994, "stop": 1658167381061, "uuid": "1b15c10f-c2fc-48b2-af77-62377bc16a9b", "historyId": "c1c8d9ab315ced79f61d6f2b0f6dbe24", "testCaseId": "99b3d4031e3c9193204afd98901cc2c8", "fullName": "tests.negative_tests.test_authorization_user_negative.TestAuthorizationRegistrationNegative#test_authorization_with_invalid_credentials_negative", "labels": [{"name": "severity", "value": "CRITICAL"}, {"name": "tag", "value": "@pytest.mark.usefixtures('set_up_webdriver')"}, {"name": "parentSuite", "value": "tests.negative_tests"}, {"name": "suite", "value": "test_authorization_user_negative"}, {"name": "subSuite", "value": "TestAuthorizationRegistrationNegative"}, {"name": "host", "value": "vladislav-G3-3579"}, {"name": "thread", "value": "100642-MainThread"}, {"name": "framework", "value": "pytest"}, {"name": "language", "value": "cpython3"}, {"name": "package", "value": "tests.negative_tests.test_authorization_user_negative"}]}